2025-08-09 12:04:04,412 - ERROR - [vector_store_client.py:269] - Error searching similar vectors in collection query_embeddings: HTTPConnectionPool(host='localhost', port=8001): Max retries exceeded with url: /collections/query_embeddings/search (Caused by NewConnectionError('<urllib3.connection.HTTPConnection object at 0x7b0213c2c350>: Failed to establish a new connection: [Errno 111] Connection refused'))
Traceback (most recent call last):
  File "/home/vijay/anaconda3/lib/python3.11/site-packages/urllib3/connection.py", line 203, in _new_conn
    sock = connection.create_connection(
           ^^^^^^^^^^^^^^^^^^^^^^^^^^^^^
  File "/home/vijay/anaconda3/lib/python3.11/site-packages/urllib3/util/connection.py", line 85, in create_connection
    raise err
  File "/home/vijay/anaconda3/lib/python3.11/site-packages/urllib3/util/connection.py", line 73, in create_connection
    sock.connect(sa)
ConnectionRefusedError: [Errno 111] Connection refused

The above exception was the direct cause of the following exception:

Traceback (most recent call last):
  File "/home/vijay/anaconda3/lib/python3.11/site-packages/urllib3/connectionpool.py", line 791, in urlopen
    response = self._make_request(
               ^^^^^^^^^^^^^^^^^^^
  File "/home/vijay/anaconda3/lib/python3.11/site-packages/urllib3/connectionpool.py", line 497, in _make_request
    conn.request(
  File "/home/vijay/anaconda3/lib/python3.11/site-packages/urllib3/connection.py", line 395, in request
    self.endheaders()
  File "/home/vijay/anaconda3/lib/python3.11/http/client.py", line 1289, in endheaders
    self._send_output(message_body, encode_chunked=encode_chunked)
  File "/home/vijay/anaconda3/lib/python3.11/http/client.py", line 1048, in _send_output
    self.send(msg)
  File "/home/vijay/anaconda3/lib/python3.11/http/client.py", line 986, in send
    self.connect()
  File "/home/vijay/anaconda3/lib/python3.11/site-packages/urllib3/connection.py", line 243, in connect
    self.sock = self._new_conn()
                ^^^^^^^^^^^^^^^^
  File "/home/vijay/anaconda3/lib/python3.11/site-packages/urllib3/connection.py", line 218, in _new_conn
    raise NewConnectionError(
urllib3.exceptions.NewConnectionError: <urllib3.connection.HTTPConnection object at 0x7b0213c2c350>: Failed to establish a new connection: [Errno 111] Connection refused

The above exception was the direct cause of the following exception:

Traceback (most recent call last):
  File "/home/vijay/anaconda3/lib/python3.11/site-packages/requests/adapters.py", line 486, in send
    resp = conn.urlopen(
           ^^^^^^^^^^^^^
  File "/home/vijay/anaconda3/lib/python3.11/site-packages/urllib3/connectionpool.py", line 845, in urlopen
    retries = retries.increment(
              ^^^^^^^^^^^^^^^^^^
  File "/home/vijay/anaconda3/lib/python3.11/site-packages/urllib3/util/retry.py", line 515, in increment
    raise MaxRetryError(_pool, url, reason) from reason  # type: ignore[arg-type]
    ^^^^^^^^^^^^^^^^^^^^^^^^^^^^^^^^^^^^^^^^^^^^^^^^^^^
urllib3.exceptions.MaxRetryError: HTTPConnectionPool(host='localhost', port=8001): Max retries exceeded with url: /collections/query_embeddings/search (Caused by NewConnectionError('<urllib3.connection.HTTPConnection object at 0x7b0213c2c350>: Failed to establish a new connection: [Errno 111] Connection refused'))

During handling of the above exception, another exception occurred:

Traceback (most recent call last):
  File "/home/vijay/gitrepo/text2sql/src/utils/vector_store_client.py", line 238, in search_similar
    response = self.session.post(
               ^^^^^^^^^^^^^^^^^^
  File "/home/vijay/anaconda3/lib/python3.11/site-packages/requests/sessions.py", line 637, in post
    return self.request("POST", url, data=data, json=json, **kwargs)
           ^^^^^^^^^^^^^^^^^^^^^^^^^^^^^^^^^^^^^^^^^^^^^^^^^^^^^^^^^
  File "/home/vijay/anaconda3/lib/python3.11/site-packages/requests/sessions.py", line 589, in request
    resp = self.send(prep, **send_kwargs)
           ^^^^^^^^^^^^^^^^^^^^^^^^^^^^^^
  File "/home/vijay/anaconda3/lib/python3.11/site-packages/requests/sessions.py", line 703, in send
    r = adapter.send(request, **kwargs)
        ^^^^^^^^^^^^^^^^^^^^^^^^^^^^^^^
  File "/home/vijay/anaconda3/lib/python3.11/site-packages/requests/adapters.py", line 519, in send
    raise ConnectionError(e, request=request)
requests.exceptions.ConnectionError: HTTPConnectionPool(host='localhost', port=8001): Max retries exceeded with url: /collections/query_embeddings/search (Caused by NewConnectionError('<urllib3.connection.HTTPConnection object at 0x7b0213c2c350>: Failed to establish a new connection: [Errno 111] Connection refused'))
2025-08-09 12:04:04,417 - ERROR - [vector_store_client.py:50] - ChromaDB service connection error: HTTPConnectionPool(host='localhost', port=8001): Max retries exceeded with url: /health (Caused by NewConnectionError('<urllib3.connection.HTTPConnection object at 0x7b02138bd310>: Failed to establish a new connection: [Errno 111] Connection refused'))
Traceback (most recent call last):
  File "/home/vijay/anaconda3/lib/python3.11/site-packages/urllib3/connection.py", line 203, in _new_conn
    sock = connection.create_connection(
           ^^^^^^^^^^^^^^^^^^^^^^^^^^^^^
  File "/home/vijay/anaconda3/lib/python3.11/site-packages/urllib3/util/connection.py", line 85, in create_connection
    raise err
  File "/home/vijay/anaconda3/lib/python3.11/site-packages/urllib3/util/connection.py", line 73, in create_connection
    sock.connect(sa)
ConnectionRefusedError: [Errno 111] Connection refused

The above exception was the direct cause of the following exception:

Traceback (most recent call last):
  File "/home/vijay/anaconda3/lib/python3.11/site-packages/urllib3/connectionpool.py", line 791, in urlopen
    response = self._make_request(
               ^^^^^^^^^^^^^^^^^^^
  File "/home/vijay/anaconda3/lib/python3.11/site-packages/urllib3/connectionpool.py", line 497, in _make_request
    conn.request(
  File "/home/vijay/anaconda3/lib/python3.11/site-packages/urllib3/connection.py", line 395, in request
    self.endheaders()
  File "/home/vijay/anaconda3/lib/python3.11/http/client.py", line 1289, in endheaders
    self._send_output(message_body, encode_chunked=encode_chunked)
  File "/home/vijay/anaconda3/lib/python3.11/http/client.py", line 1048, in _send_output
    self.send(msg)
  File "/home/vijay/anaconda3/lib/python3.11/http/client.py", line 986, in send
    self.connect()
  File "/home/vijay/anaconda3/lib/python3.11/site-packages/urllib3/connection.py", line 243, in connect
    self.sock = self._new_conn()
                ^^^^^^^^^^^^^^^^
  File "/home/vijay/anaconda3/lib/python3.11/site-packages/urllib3/connection.py", line 218, in _new_conn
    raise NewConnectionError(
urllib3.exceptions.NewConnectionError: <urllib3.connection.HTTPConnection object at 0x7b02138bd310>: Failed to establish a new connection: [Errno 111] Connection refused

The above exception was the direct cause of the following exception:

Traceback (most recent call last):
  File "/home/vijay/anaconda3/lib/python3.11/site-packages/requests/adapters.py", line 486, in send
    resp = conn.urlopen(
           ^^^^^^^^^^^^^
  File "/home/vijay/anaconda3/lib/python3.11/site-packages/urllib3/connectionpool.py", line 845, in urlopen
    retries = retries.increment(
              ^^^^^^^^^^^^^^^^^^
  File "/home/vijay/anaconda3/lib/python3.11/site-packages/urllib3/util/retry.py", line 515, in increment
    raise MaxRetryError(_pool, url, reason) from reason  # type: ignore[arg-type]
    ^^^^^^^^^^^^^^^^^^^^^^^^^^^^^^^^^^^^^^^^^^^^^^^^^^^
urllib3.exceptions.MaxRetryError: HTTPConnectionPool(host='localhost', port=8001): Max retries exceeded with url: /health (Caused by NewConnectionError('<urllib3.connection.HTTPConnection object at 0x7b02138bd310>: Failed to establish a new connection: [Errno 111] Connection refused'))

During handling of the above exception, another exception occurred:

Traceback (most recent call last):
  File "/home/vijay/gitrepo/text2sql/src/utils/vector_store_client.py", line 39, in connect
    response = self.session.get(f"{self.service_url}/health", timeout=10)
               ^^^^^^^^^^^^^^^^^^^^^^^^^^^^^^^^^^^^^^^^^^^^^^^^^^^^^^^^^^
  File "/home/vijay/anaconda3/lib/python3.11/site-packages/requests/sessions.py", line 602, in get
    return self.request("GET", url, **kwargs)
           ^^^^^^^^^^^^^^^^^^^^^^^^^^^^^^^^^^
  File "/home/vijay/anaconda3/lib/python3.11/site-packages/requests/sessions.py", line 589, in request
    resp = self.send(prep, **send_kwargs)
           ^^^^^^^^^^^^^^^^^^^^^^^^^^^^^^
  File "/home/vijay/anaconda3/lib/python3.11/site-packages/requests/sessions.py", line 703, in send
    r = adapter.send(request, **kwargs)
        ^^^^^^^^^^^^^^^^^^^^^^^^^^^^^^^
  File "/home/vijay/anaconda3/lib/python3.11/site-packages/requests/adapters.py", line 519, in send
    raise ConnectionError(e, request=request)
requests.exceptions.ConnectionError: HTTPConnectionPool(host='localhost', port=8001): Max retries exceeded with url: /health (Caused by NewConnectionError('<urllib3.connection.HTTPConnection object at 0x7b02138bd310>: Failed to establish a new connection: [Errno 111] Connection refused'))
2025-08-09 12:04:04,789 - ERROR - [llm_engine.py:263] - [SQL_GEN] Completion generation error after 0.37s: Error code: 400 - [{'error': {'code': 400, 'message': 'Developer instruction is not enabled for models/gemma-3-27b-it', 'status': 'INVALID_ARGUMENT'}}]
Traceback (most recent call last):
  File "/home/vijay/gitrepo/text2sql/src/utils/llm_engine.py", line 237, in generate_completion
    response = self.client.chat.completions.create(
               ^^^^^^^^^^^^^^^^^^^^^^^^^^^^^^^^^^^^
  File "/home/vijay/anaconda3/lib/python3.11/site-packages/openai/_utils/_utils.py", line 274, in wrapper
    return func(*args, **kwargs)
           ^^^^^^^^^^^^^^^^^^^^^
  File "/home/vijay/anaconda3/lib/python3.11/site-packages/openai/resources/chat/completions.py", line 668, in create
    return self._post(
           ^^^^^^^^^^^
  File "/home/vijay/anaconda3/lib/python3.11/site-packages/openai/_base_client.py", line 1260, in post
    return cast(ResponseT, self.request(cast_to, opts, stream=stream, stream_cls=stream_cls))
                           ^^^^^^^^^^^^^^^^^^^^^^^^^^^^^^^^^^^^^^^^^^^^^^^^^^^^^^^^^^^^^^^^^
  File "/home/vijay/anaconda3/lib/python3.11/site-packages/openai/_base_client.py", line 937, in request
    return self._request(
           ^^^^^^^^^^^^^^
  File "/home/vijay/anaconda3/lib/python3.11/site-packages/openai/_base_client.py", line 1041, in _request
    raise self._make_status_error_from_response(err.response) from None
openai.BadRequestError: Error code: 400 - [{'error': {'code': 400, 'message': 'Developer instruction is not enabled for models/gemma-3-27b-it', 'status': 'INVALID_ARGUMENT'}}]
2025-08-09 12:04:04,805 - ERROR - [azure_client.py:138] - SQL generation error after 0.39s: Error code: 400 - [{'error': {'code': 400, 'message': 'Developer instruction is not enabled for models/gemma-3-27b-it', 'status': 'INVALID_ARGUMENT'}}]
Traceback (most recent call last):
  File "/home/vijay/gitrepo/text2sql/src/utils/azure_client.py", line 117, in generate_sql
    raw_response = self.llm_engine.generate_completion(messages, log_prefix="SQL_GEN")
                   ^^^^^^^^^^^^^^^^^^^^^^^^^^^^^^^^^^^^^^^^^^^^^^^^^^^^^^^^^^^^^^^^^^^
  File "/home/vijay/gitrepo/text2sql/src/utils/llm_engine.py", line 237, in generate_completion
    response = self.client.chat.completions.create(
               ^^^^^^^^^^^^^^^^^^^^^^^^^^^^^^^^^^^^
  File "/home/vijay/anaconda3/lib/python3.11/site-packages/openai/_utils/_utils.py", line 274, in wrapper
    return func(*args, **kwargs)
           ^^^^^^^^^^^^^^^^^^^^^
  File "/home/vijay/anaconda3/lib/python3.11/site-packages/openai/resources/chat/completions.py", line 668, in create
    return self._post(
           ^^^^^^^^^^^
  File "/home/vijay/anaconda3/lib/python3.11/site-packages/openai/_base_client.py", line 1260, in post
    return cast(ResponseT, self.request(cast_to, opts, stream=stream, stream_cls=stream_cls))
                           ^^^^^^^^^^^^^^^^^^^^^^^^^^^^^^^^^^^^^^^^^^^^^^^^^^^^^^^^^^^^^^^^^
  File "/home/vijay/anaconda3/lib/python3.11/site-packages/openai/_base_client.py", line 937, in request
    return self._request(
           ^^^^^^^^^^^^^^
  File "/home/vijay/anaconda3/lib/python3.11/site-packages/openai/_base_client.py", line 1041, in _request
    raise self._make_status_error_from_response(err.response) from None
openai.BadRequestError: Error code: 400 - [{'error': {'code': 400, 'message': 'Developer instruction is not enabled for models/gemma-3-27b-it', 'status': 'INVALID_ARGUMENT'}}]
2025-08-09 12:04:46,793 - ERROR - [llm_engine.py:263] - [SQL_GEN] Completion generation error after 0.37s: Error code: 400 - [{'error': {'code': 400, 'message': 'Developer instruction is not enabled for models/gemma-3-27b-it', 'status': 'INVALID_ARGUMENT'}}]
Traceback (most recent call last):
  File "/home/vijay/gitrepo/text2sql/src/utils/llm_engine.py", line 237, in generate_completion
    response = self.client.chat.completions.create(
               ^^^^^^^^^^^^^^^^^^^^^^^^^^^^^^^^^^^^
  File "/home/vijay/anaconda3/lib/python3.11/site-packages/openai/_utils/_utils.py", line 274, in wrapper
    return func(*args, **kwargs)
           ^^^^^^^^^^^^^^^^^^^^^
  File "/home/vijay/anaconda3/lib/python3.11/site-packages/openai/resources/chat/completions.py", line 668, in create
    return self._post(
           ^^^^^^^^^^^
  File "/home/vijay/anaconda3/lib/python3.11/site-packages/openai/_base_client.py", line 1260, in post
    return cast(ResponseT, self.request(cast_to, opts, stream=stream, stream_cls=stream_cls))
                           ^^^^^^^^^^^^^^^^^^^^^^^^^^^^^^^^^^^^^^^^^^^^^^^^^^^^^^^^^^^^^^^^^
  File "/home/vijay/anaconda3/lib/python3.11/site-packages/openai/_base_client.py", line 937, in request
    return self._request(
           ^^^^^^^^^^^^^^
  File "/home/vijay/anaconda3/lib/python3.11/site-packages/openai/_base_client.py", line 1041, in _request
    raise self._make_status_error_from_response(err.response) from None
openai.BadRequestError: Error code: 400 - [{'error': {'code': 400, 'message': 'Developer instruction is not enabled for models/gemma-3-27b-it', 'status': 'INVALID_ARGUMENT'}}]
2025-08-09 12:04:46,800 - ERROR - [azure_client.py:138] - SQL generation error after 0.38s: Error code: 400 - [{'error': {'code': 400, 'message': 'Developer instruction is not enabled for models/gemma-3-27b-it', 'status': 'INVALID_ARGUMENT'}}]
Traceback (most recent call last):
  File "/home/vijay/gitrepo/text2sql/src/utils/azure_client.py", line 117, in generate_sql
    raw_response = self.llm_engine.generate_completion(messages, log_prefix="SQL_GEN")
                   ^^^^^^^^^^^^^^^^^^^^^^^^^^^^^^^^^^^^^^^^^^^^^^^^^^^^^^^^^^^^^^^^^^^
  File "/home/vijay/gitrepo/text2sql/src/utils/llm_engine.py", line 237, in generate_completion
    response = self.client.chat.completions.create(
               ^^^^^^^^^^^^^^^^^^^^^^^^^^^^^^^^^^^^
  File "/home/vijay/anaconda3/lib/python3.11/site-packages/openai/_utils/_utils.py", line 274, in wrapper
    return func(*args, **kwargs)
           ^^^^^^^^^^^^^^^^^^^^^
  File "/home/vijay/anaconda3/lib/python3.11/site-packages/openai/resources/chat/completions.py", line 668, in create
    return self._post(
           ^^^^^^^^^^^
  File "/home/vijay/anaconda3/lib/python3.11/site-packages/openai/_base_client.py", line 1260, in post
    return cast(ResponseT, self.request(cast_to, opts, stream=stream, stream_cls=stream_cls))
                           ^^^^^^^^^^^^^^^^^^^^^^^^^^^^^^^^^^^^^^^^^^^^^^^^^^^^^^^^^^^^^^^^^
  File "/home/vijay/anaconda3/lib/python3.11/site-packages/openai/_base_client.py", line 937, in request
    return self._request(
           ^^^^^^^^^^^^^^
  File "/home/vijay/anaconda3/lib/python3.11/site-packages/openai/_base_client.py", line 1041, in _request
    raise self._make_status_error_from_response(err.response) from None
openai.BadRequestError: Error code: 400 - [{'error': {'code': 400, 'message': 'Developer instruction is not enabled for models/gemma-3-27b-it', 'status': 'INVALID_ARGUMENT'}}]
2025-08-09 12:07:01,474 - ERROR - [llm_engine.py:263] - [Knowledge QA] Completion generation error after 0.33s: Error code: 400 - [{'error': {'code': 400, 'message': 'Developer instruction is not enabled for models/gemma-3-27b-it', 'status': 'INVALID_ARGUMENT'}}]
Traceback (most recent call last):
  File "/home/vijay/gitrepo/text2sql/src/utils/llm_engine.py", line 203, in generate_completion
    response = self.client.chat.completions.create(
               ^^^^^^^^^^^^^^^^^^^^^^^^^^^^^^^^^^^^
  File "/home/vijay/anaconda3/lib/python3.11/site-packages/openai/_utils/_utils.py", line 274, in wrapper
    return func(*args, **kwargs)
           ^^^^^^^^^^^^^^^^^^^^^
  File "/home/vijay/anaconda3/lib/python3.11/site-packages/openai/resources/chat/completions.py", line 668, in create
    return self._post(
           ^^^^^^^^^^^
  File "/home/vijay/anaconda3/lib/python3.11/site-packages/openai/_base_client.py", line 1260, in post
    return cast(ResponseT, self.request(cast_to, opts, stream=stream, stream_cls=stream_cls))
                           ^^^^^^^^^^^^^^^^^^^^^^^^^^^^^^^^^^^^^^^^^^^^^^^^^^^^^^^^^^^^^^^^^
  File "/home/vijay/anaconda3/lib/python3.11/site-packages/openai/_base_client.py", line 937, in request
    return self._request(
           ^^^^^^^^^^^^^^
  File "/home/vijay/anaconda3/lib/python3.11/site-packages/openai/_base_client.py", line 1041, in _request
    raise self._make_status_error_from_response(err.response) from None
openai.BadRequestError: Error code: 400 - [{'error': {'code': 400, 'message': 'Developer instruction is not enabled for models/gemma-3-27b-it', 'status': 'INVALID_ARGUMENT'}}]
2025-08-09 12:09:15,957 - ERROR - [llm_engine.py:263] - [MCP-ServerSelection] Completion generation error after 0.34s: Error code: 400 - [{'error': {'code': 400, 'message': 'Developer instruction is not enabled for models/gemma-3-27b-it', 'status': 'INVALID_ARGUMENT'}}]
Traceback (most recent call last):
  File "/home/vijay/gitrepo/text2sql/src/utils/llm_engine.py", line 237, in generate_completion
    response = self.client.chat.completions.create(
               ^^^^^^^^^^^^^^^^^^^^^^^^^^^^^^^^^^^^
  File "/home/vijay/anaconda3/lib/python3.11/site-packages/openai/_utils/_utils.py", line 274, in wrapper
    return func(*args, **kwargs)
           ^^^^^^^^^^^^^^^^^^^^^
  File "/home/vijay/anaconda3/lib/python3.11/site-packages/openai/resources/chat/completions.py", line 668, in create
    return self._post(
           ^^^^^^^^^^^
  File "/home/vijay/anaconda3/lib/python3.11/site-packages/openai/_base_client.py", line 1260, in post
    return cast(ResponseT, self.request(cast_to, opts, stream=stream, stream_cls=stream_cls))
                           ^^^^^^^^^^^^^^^^^^^^^^^^^^^^^^^^^^^^^^^^^^^^^^^^^^^^^^^^^^^^^^^^^
  File "/home/vijay/anaconda3/lib/python3.11/site-packages/openai/_base_client.py", line 937, in request
    return self._request(
           ^^^^^^^^^^^^^^
  File "/home/vijay/anaconda3/lib/python3.11/site-packages/openai/_base_client.py", line 1041, in _request
    raise self._make_status_error_from_response(err.response) from None
openai.BadRequestError: Error code: 400 - [{'error': {'code': 400, 'message': 'Developer instruction is not enabled for models/gemma-3-27b-it', 'status': 'INVALID_ARGUMENT'}}]
2025-08-09 12:09:15,958 - ERROR - [mcp_client_manager.py:1236] - Error selecting MCP server for query
Traceback (most recent call last):
  File "/home/vijay/gitrepo/text2sql/src/utils/mcp_client_manager.py", line 1208, in select_server_for_query
    response = llm_engine.generate_completion(
               ^^^^^^^^^^^^^^^^^^^^^^^^^^^^^^^
  File "/home/vijay/gitrepo/text2sql/src/utils/llm_engine.py", line 237, in generate_completion
    response = self.client.chat.completions.create(
               ^^^^^^^^^^^^^^^^^^^^^^^^^^^^^^^^^^^^
  File "/home/vijay/anaconda3/lib/python3.11/site-packages/openai/_utils/_utils.py", line 274, in wrapper
    return func(*args, **kwargs)
           ^^^^^^^^^^^^^^^^^^^^^
  File "/home/vijay/anaconda3/lib/python3.11/site-packages/openai/resources/chat/completions.py", line 668, in create
    return self._post(
           ^^^^^^^^^^^
  File "/home/vijay/anaconda3/lib/python3.11/site-packages/openai/_base_client.py", line 1260, in post
    return cast(ResponseT, self.request(cast_to, opts, stream=stream, stream_cls=stream_cls))
                           ^^^^^^^^^^^^^^^^^^^^^^^^^^^^^^^^^^^^^^^^^^^^^^^^^^^^^^^^^^^^^^^^^
  File "/home/vijay/anaconda3/lib/python3.11/site-packages/openai/_base_client.py", line 937, in request
    return self._request(
           ^^^^^^^^^^^^^^
  File "/home/vijay/anaconda3/lib/python3.11/site-packages/openai/_base_client.py", line 1041, in _request
    raise self._make_status_error_from_response(err.response) from None
openai.BadRequestError: Error code: 400 - [{'error': {'code': 400, 'message': 'Developer instruction is not enabled for models/gemma-3-27b-it', 'status': 'INVALID_ARGUMENT'}}]
2025-08-09 12:09:16,204 - ERROR - [mcp_client_manager.py:275] - Error connecting to SSE endpoint: http://localhost:8003/sse - unhandled errors in a TaskGroup (1 sub-exception)
2025-08-09 12:14:41,482 - ERROR - [mcp_client_manager.py:275] - Error connecting to SSE endpoint: http://localhost:8003/sse - unhandled errors in a TaskGroup (1 sub-exception)
